Workbook
Name Region: 'dynamic chart'!$P$3
Name Slicer_Customer_Name: #N/A
Name Slicer_Customer_Name1: #N/A
Name Slicer_Order_Date__Month: #N/A
Name Slicer_Order_Date__Quarter: #N/A
Name Slicer_Order_Date__Year: #N/A
Name Slicer_Product_Category: #N/A
Name Slicer_Product_Name: #N/A
Name Slicer_Region: #N/A
Name Slicer_Total_Sales: #N/A
Name Years__Order_Date: ' Charts'!$A$61:$D$74

Sheet Assignment Questions
B1: Use Main Data Sheet and Product_Lookup Sheet to solve the below Questions | C1: Criteria | D1: ANSWERS
B3: Sort the data by Order Date in ascending order. | D3: Main Data'!A1
B4: Filter data for Region = "North". | D4: Main Data'!J1
B5: Use COUNTIF to count how many times "Laptop" appears in Product Name. | C5: Laptop | D5: =COUNTIF('Main Data'!F2:F1001,C5) -> 116
B6: Use SUMIF to calculate total sales for the "West" region. | C6: West | D6: =SUMIF('Main Data'!D2:D1001,'Assignment Questions'!C6,'Main Data'!I2:I1001) -> 595706.23
B7: Calculate total revenue using a formula (Quantity * Unit Price).
B8: Use IF to label sales above 5000 as “High” and others as “Low”. | D8: Main Data'!A1
B9: Extract the year from Order Date using YEAR function. | D9: Main Data'!A1
B10: Format Unit Price column as currency. | D10: Main Data'!A1
B11: Use PROPER to capitalize all customer names correctly. | D11: Main Data'!A1
B12: Create a bar chart showing total sales by Region. | D12: Bar Chart'!A1
B13: Use VLOOKUP to find unit price of a specific product.
B14: Find the average quantity ordered using AVERAGE. | C14: Average | D14: =AVERAGE('sales data'!G2:G1001) -> 4.898
B15: Use MAX and MIN to find the highest and lowest Total Sales. | C15: MAX | D15: =MAX('sales data'!I2:I1001) -> 8890.65
C16: MIN | D16: =MIN('sales data'!I2:I1001) -> 15.7
B17: Add a new column for Discounted Price = Unit Price * 0.9. | D17: sales data'!A1
B18: Use TEXT function to convert Order Date into MMM-YYYY format. | D18: sales data'!A1
B19: Highlight rows where Quantity > 5 using conditional formatting. | D19: sales data'!A1
B20: Freeze the top row for easier navigation. | D20: sales data'!A1
B21: Rename the sheet as “Sales Data”. | D21: sales data'!A1
B22: Use advance filter, to filter the data, take few criteria like region, category, name etc | D22: sales data'!P1
B23: Add filters to all columns. | D23: sales data'!P1
B25: Use VLOOKUP to retrieve the Supplier name for each Product Name. | D25: Product_Lookup Data'!D13
B26: Use XLOOKUP to find the Stock Available from the Product_Lookup sheet. | D26: Product_Lookup Data'!D23
B27: Use COUNTIFS to count how many "Laptops" were sold in the "East" region. | C27: East & Laptop | D27: =COUNTIFS('Main Data'!D2:D1001,"East",'Main Data'!F2:F1001,"Laptop") -> 30
B28: Create a Pivot Table showing total sales by Region and Product Category. | D28: Bar Chart'!A21
B29: Add a slicer to filter the pivot table by Customer Name. | D29: Bar Chart'!A21
B30: Use AVERAGEIFS to calculate average Unit Price for each Region. | D30: =HYPERLINK('Main Data'!T2) -> North
B31: Create a line chart showing monthly sales trend. | D31: Charts'!D42
B32: Use YEAR and MONTH functions to extract month-year from Order Date. | D32: =HYPERLINK('Main Data'!Q2) -> 4
B33: Apply conditional formatting to highlight top 10 Total Sales. | D33: Main Data'!i165
B34: Create a new column to calculate sales tax (e.g., 18% of Total Sales). | D34: sales data'!P2
B35: Use LEFT, RIGHT, MID to extract parts of Product ID. | D35: Product_Lookup Data'!G1
B36: Use a function to combine Product Name and Product Category into one cell. | D36: sales data'!Q2
B37: Use Remove Duplicates to clean repeated rows (if any).
B38: Create a dynamic chart using drop-down linked to data. | D38: dynamic chart'!O1
B39: Group Order Date by month and year in a pivot table. | D39: =HYPERLINK('Pivot table'!A1) -> Order Date (Month)
B40: Create a histogram of Unit Price. | D40: Pivot table'!D5
B41: Use GOAL SEEK to determine quantity needed to reach ₹10,000 in sales.
B43: Use nested IF statements to classify sales into High (≥8000), Medium (3000–7999), and Low (<3000) | D43: sales data'!R2
...

Sheet Main Data
A1: Order ID | B1: Order Date | C1: Customer Name | D1: Region | E1: Product Category | F1: Product Name | G1: Quantity | H1: Unit Price | I1: Total Sales | J1: Total Revenue | K1: Sales Type | L1: year | M1: PROPER | N1: CAPITAL | O1: DISCOUNTED PRICE | P1: TEXT | Q1: month-2 | R1: Year-2 | T1: Average Unit price by region | U1: Amount
A2: 8516 | B2: 45023 | C2: Turner LLC | D2: North | E2: Electronics | F2: Laptop | G2: 6 | H2: 874.94 | I2: 5249.64 | J2: =G2*H2 -> 5249.64 | K2: =IF('Main Data'!I2>=5000,"High", "Low") -> High | L2: =YEAR(B2) -> 2023 | M2: =PROPER(C2) -> Turner Llc | N2: =UPPER(C2) -> TURNER LLC | O2: =G2*(H2*0.9) -> 4724.676 | P2: =TEXT((B2),"mmm-yyyy") -> Apr-2023 | Q2: =MONTH(B2) -> 4 | R2: =YEAR(B2) -> 2023 | T2: North | U2: =AVERAGEIF($D$2:$D$1001,T2,$H$2:$H$1001) -> 507.28012
A3: 3328 | B3: 45023 | C3: Wesley Davis | D3: South | E3: Furniture | F3: Chair | G3: 3 | H3: 659.6 | I3: 1978.8 | J3: =G3*H3 -> 1978.8 | K3: =IF('Main Data'!I3>=5000,"High", "Low") -> Low | L3: =YEAR(B3) -> 2023 | M3: =PROPER(C3) -> Wesley Davis | N3: =UPPER(C3) -> WESLEY DAVIS | O3: =G3*(H3*0.9) -> 1780.92 | P3: =TEXT((B3),"mmm-yyyy") -> Apr-2023 | Q3: =MONTH(B3) -> 4 | R3: =YEAR(B3) -> 2023 | T3: South | U3: =AVERAGEIF($D$2:$D$1001,T3,$H$2:$H$1001) -> 495.8824
A4: 8895 | B4: 45024 | C4: Brandi Berg | D4: East | E4: Furniture | F4: Chair | G4: 7 | H4: 115.91 | I4: 811.37 | J4: =G4*H4 -> 811.37 | K4: =IF('Main Data'!I4>=5000,"High", "Low") -> Low | L4: =YEAR(B4) -> 2023 | M4: =PROPER(C4) -> Brandi Berg | N4: =UPPER(C4) -> BRANDI BERG | O4: =G4*(H4*0.9) -> 730.233 | P4: =TEXT((B4),"mmm-yyyy") -> Apr-2023 | Q4: =MONTH(B4) -> 4 | R4: =YEAR(B4) -> 2023 | T4: East | U4: =AVERAGEIF($D$2:$D$1001,T4,$H$2:$H$1001) -> 488.61509
A5: 8412 | B5: 45025 | C5: William Morgan | D5: North | E5: Electronics | F5: Printer | G5: 2 | H5: 481.29 | I5: 962.58 | J5: =G5*H5 -> 962.58 | K5: =IF('Main Data'!I5>=5000,"High", "Low") -> Low | L5: =YEAR(B5) -> 2023 | M5: =PROPER(C5) -> William Morgan | N5: =UPPER(C5) -> WILLIAM MORGAN | O5: =G5*(H5*0.9) -> 866.322 | P5: =TEXT((B5),"mmm-yyyy") -> Apr-2023 | Q5: =MONTH(B5) -> 4 | R5: =YEAR(B5) -> 2023 | T5: West | U5: =AVERAGEIF($D$2:$D$1001,T5,$H$2:$H$1001) -> 547.19846
A6: 4451 | B6: 45025 | C6: Mr. Dakota Owens | D6: East | E6: Furniture | F6: Monitor | G6: 1 | H6: 661.87 | I6: 661.87 | J6: =G6*H6 -> 661.87 | K6: =IF('Main Data'!I6>=5000,"High", "Low") -> Low | L6: =YEAR(B6) -> 2023 | M6: =PROPER(C6) -> Mr. Dakota Owens | N6: =UPPER(C6) -> MR. DAKOTA OWENS | O6: =G6*(H6*0.9) -> 595.683 | P6: =TEXT((B6),"mmm-yyyy") -> Apr-2023 | Q6: =MONTH(B6) -> 4 | R6: =YEAR(B6) -> 2023
A7: 5863 | B7: 45025 | C7: William Barber DDS | D7: North | E7: Office Supplies | F7: Desk | G7: 4 | H7: 377.33 | I7: 1509.32 | J7: =G7*H7 -> 1509.32 | K7: =IF('Main Data'!I7>=5000,"High", "Low") -> Low | L7: =YEAR(B7) -> 2023 | M7: =PROPER(C7) -> William Barber Dds | N7: =UPPER(C7) -> WILLIAM BARBER DDS | O7: =G7*(H7*0.9) -> 1358.388 | P7: =TEXT((B7),"mmm-yyyy") -> Apr-2023 | Q7: =MONTH(B7) -> 4 | R7: =YEAR(B7) -> 2023
A8: 2915 | B8: 45025 | C8: Robert Mack | D8: South | E8: Furniture | F8: Notebook | G8: 8 | H8: 869.46 | I8: 6955.68 | J8: =G8*H8 -> 6955.68 | K8: =IF('Main Data'!I8>=5000,"High", "Low") -> High | L8: =YEAR(B8) -> 2023 | M8: =PROPER(C8) -> Robert Mack | N8: =UPPER(C8) -> ROBERT MACK | O8: =G8*(H8*0.9) -> 6260.112 | P8: =TEXT((B8),"mmm-yyyy") -> Apr-2023 | Q8: =MONTH(B8) -> 4 | R8: =YEAR(B8) -> 2023
A9: 2315 | B9: 45026 | C9: David Greene | D9: South | E9: Electronics | F9: Chair | G9: 1 | H9: 983.84 | I9: 983.84 | J9: =G9*H9 -> 983.84 | K9: =IF('Main Data'!I9>=5000,"High", "Low") -> Low | L9: =YEAR(B9) -> 2023 | M9: =PROPER(C9) -> David Greene | N9: =UPPER(C9) -> DAVID GREENE | O9: =G9*(H9*0.9) -> 885.456 | P9: =TEXT((B9),"mmm-yyyy") -> Apr-2023 | Q9: =MONTH(B9) -> 4 | R9: =YEAR(B9) -> 2023
A10: 7129 | B10: 45027 | C10: Janice Hammond | D10: East | E10: Electronics | F10: Chair | G10: 1 | H10: 115.53 | I10: 115.53 | J10: =G10*H10 -> 115.53 | K10: =IF('Main Data'!I10>=5000,"High", "Low") -> Low | L10: =YEAR(B10) -> 2023 | M10: =PROPER(C10) -> Janice Hammond | N10: =UPPER(C10) -> JANICE HAMMOND | O10: =G10*(H10*0.9) -> 103.977 | P10: =TEXT((B10),"mmm-yyyy") -> Apr-2023 | Q10: =MONTH(B10) -> 4 | R10: =YEAR(B10) -> 2023
A11: 1822 | B11: 45029 | C11: Daniel Griffin Jr. | D11: North | E11: Office Supplies | F11: Notebook | G11: 8 | H11: 925.15 | I11: 7401.2 | J11: =G11*H11 -> 7401.2 | K11: =IF('Main Data'!I11>=5000,"High", "Low") -> High | L11: =YEAR(B11) -> 2023 | M11: =PROPER(C11) -> Daniel Griffin Jr. | N11: =UPPER(C11) -> DANIEL GRIFFIN JR. | O11: =G11*(H11*0.9) -> 6661.08 | P11: =TEXT((B11),"mmm-yyyy") -> Apr-2023 | Q11: =MONTH(B11) -> 4 | R11: =YEAR(B11) -> 2023
A12: 2951 | B12: 45029 | C12: Sara Harrison | D12: West | E12: Office Supplies | F12: Chair | G12: 6 | H12: 357.2 | I12: 2143.2 | J12: =G12*H12 -> 2143.2 | K12: =IF('Main Data'!I12>=5000,"High", "Low") -> Low | L12: =YEAR(B12) -> 2023 | M12: =PROPER(C12) -> Sara Harrison | N12: =UPPER(C12) -> SARA HARRISON | O12: =G12*(H12*0.9) -> 1928.88 | P12: =TEXT((B12),"mmm-yyyy") -> Apr-2023 | Q12: =MONTH(B12) -> 4 | R12: =YEAR(B12) -> 2023
A13: 6869 | B13: 45029 | C13: Kathleen King | D13: South | E13: Furniture | F13: Laptop | G13: 6 | H13: 782.95 | I13: 4697.7 | J13: =G13*H13 -> 4697.7 | K13: =IF('Main Data'!I13>=5000,"High", "Low") -> Low | L13: =YEAR(B13) -> 2023 | M13: =PROPER(C13) -> Kathleen King | N13: =UPPER(C13) -> KATHLEEN KING | O13: =G13*(H13*0.9) -> 4227.93 | P13: =TEXT((B13),"mmm-yyyy") -> Apr-2023 | Q13: =MONTH(B13) -> 4 | R13: =YEAR(B13) -> 2023
A14: 6012 | B14: 45031 | C14: Charles Stokes | D14: West | E14: Electronics | F14: Laptop | G14: 4 | H14: 421.99 | I14: 1687.96 | J14: =G14*H14 -> 1687.96 | K14: =IF('Main Data'!I14>=5000,"High", "Low") -> Low | L14: =YEAR(B14) -> 2023 | M14: =PROPER(C14) -> Charles Stokes | N14: =UPPER(C14) -> CHARLES STOKES | O14: =G14*(H14*0.9) -> 1519.164 | P14: =TEXT((B14),"mmm-yyyy") -> Apr-2023 | Q14: =MONTH(B14) -> 4 | R14: =YEAR(B14) -> 2023
A15: 2481 | B15: 45032 | C15: Terry Fisher | D15: West | E15: Furniture | F15: Monitor | G15: 2 | H15: 880.33 | I15: 1760.66 | J15: =G15*H15 -> 1760.66 | K15: =IF('Main Data'!I15>=5000,"High", "Low") -> Low | L15: =YEAR(B15) -> 2023 | M15: =PROPER(C15) -> Terry Fisher | N15: =UPPER(C15) -> TERRY FISHER | O15: =G15*(H15*0.9) -> 1584.594 | P15: =TEXT((B15),"mmm-yyyy") -> Apr-2023 | Q15: =MONTH(B15) -> 4 | R15: =YEAR(B15) -> 2023
A16: 1921 | B16: 45032 | C16: Alexander Johnson | D16: West | E16: Furniture | F16: Laptop | G16: 6 | H16: 739.98 | I16: 4439.88 | J16: =G16*H16 -> 4439.88 | K16: =IF('Main Data'!I16>=5000,"High", "Low") -> Low | L16: =YEAR(B16) -> 2023 | M16: =PROPER(C16) -> Alexander Johnson | N16: =UPPER(C16) -> ALEXANDER JOHNSON | O16: =G16*(H16*0.9) -> 3995.892 | P16: =TEXT((B16),"mmm-yyyy") -> Apr-2023 | Q16: =MONTH(B16) -> 4 | R16: =YEAR(B16) -> 2023
A17: 5895 | B17: 45032 | C17: Christopher Herman | D17: South | E17: Electronics | F17: Notebook | G17: 1 | H17: 649.35 | I17: 649.35 | J17: =G17*H17 -> 649.35 | K17: =IF('Main Data'!I17>=5000,"High", "Low") -> Low | L17: =YEAR(B17) -> 2023 | M17: =PROPER(C17) -> Christopher Herman | N17: =UPPER(C17) -> CHRISTOPHER HERMAN | O17: =G17*(H17*0.9) -> 584.415 | P17: =TEXT((B17),"mmm-yyyy") -> Apr-2023 | Q17: =MONTH(B17) -> 4 | R17: =YEAR(B17) -> 2023
... A1001: 3344 | B1001: 45751 | C1001: Taylor Lowe | D1001: North | E1001: Furniture | F1001: Notebook | G1001: 2 | H1001: 757.49 | I1001: 1514.98 | J1001: =G1001*H1001 -> 1514.98 | K1001: =IF('Main Data'!I1001>=5000,"High", "Low") -> Low | L1001: =YEAR(B1001) -> 2025 | M1001: =PROPER(C1001) -> Taylor Lowe | N1001: =UPPER(C1001) -> TAYLOR LOWE | O1001: =G1001*(H1001*0.9) -> 1363.482 | P1001: =TEXT((B1001),"mmm-yyyy") -> Apr-2025 | Q1001: =MONTH(B1001) -> 4 | R1001: =YEAR(B1001) -> 2025

Sheet sales data
A1: Order ID | B1: Order Date | C1: Customer Name | D1: Region | E1: Product Category | F1: Product Name | G1: Quantity | H1: Unit Price | I1: Total Sales | J1: Sales Type | K1: year | L1: PROPER | M1: CAPITAL | N1: DISCOUNTED PRICE | O1: TEXT | P1: SALES TAX 18% | Q1: CONCATENATE' | R1: Sales Range | S1: customer catergorization | T1: Moving Average
A2: 8516 | B2: 45023 | C2: Turner LLC | D2: North | E2: Electronics | F2: Laptop | G2: 6 | H2: 874.94 | I2: 5249.64 | J2: =IF('Main Data'!I2>=5000,"High", "Low") -> High | K2: =YEAR(B2) -> 2023 | L2: =PROPER(C2) -> Turner Llc | M2: =UPPER(C2) -> TURNER LLC | N2: =G2*(H2*0.9) -> 4724.676 | O2: =TEXT((B2),"mmm-yyyy") -> Apr-2023 | P2: =I2*18% -> 944.9352 | Q2: =CONCATENATE(F2," ",E2) -> Laptop Electronics | R2: =IF('sales data'!I2<3000,"Low",IF('sales data'!I2<7999, "Medium","High")) -> Medium | S2: =IF(A2=_xlfn.MINIFS($A$3:$A$1001, $B$2:$B$1000, B2), "First Timer", "Regular") -> Regular | V2: Row Labels | W2: Sum of Total Sales
A3: 3328 | B3: 45023 | C3: Wesley Davis | D3: South | E3: Furniture | F3: Chair | G3: 3 | H3: 659.6 | I3: 1978.8 | J3: =IF('Main Data'!I3>=5000,"High", "Low") -> Low | K3: =YEAR(B3) -> 2023 | L3: =PROPER(C3) -> Wesley Davis | M3: =UPPER(C3) -> WESLEY DAVIS | N3: =G3*(H3*0.9) -> 1780.92 | O3: =TEXT((B3),"mmm-yyyy") -> Apr-2023 | P3: =I3*18% -> 356.184 | Q3: =CONCATENATE(F3," ",E3) -> Chair Furniture | R3: =IF('sales data'!I3<3000,"Low",IF('sales data'!I3<7999, "Medium","High")) -> Low | S3: =IF(A3=_xlfn.MINIFS($A$3:$A$1001, $B$2:$B$1000, B3), "First Timer", "Regular") -> First Timer | V3: East | W3: 604407.96
A4: 8895 | B4: 45024 | C4: Brandi Berg | D4: East | E4: Furniture | F4: Chair | G4: 7 | H4: 115.91 | I4: 811.37 | J4: =IF('Main Data'!I4>=5000,"High", "Low") -> Low | K4: =YEAR(B4) -> 2023 | L4: =PROPER(C4) -> Brandi Berg | M4: =UPPER(C4) -> BRANDI BERG | N4: =G4*(H4*0.9) -> 730.233 | O4: =TEXT((B4),"mmm-yyyy") -> Apr-2023 | P4: =I4*18% -> 146.0466 | Q4: =CONCATENATE(F4," ",E4) -> Chair Furniture | R4: =IF('sales data'!I4<3000,"Low",IF('sales data'!I4<7999, "Medium","High")) -> Low | S4: =IF(A4=_xlfn.MINIFS($A$3:$A$1001, $B$2:$B$1000, B4), "First Timer", "Regular") -> Regular | T4: =AVERAGE(I2,I3,I4) -> 2679.9367 | V4: Electronics | W4: 211359.11
A5: 8412 | B5: 45025 | C5: William Morgan | D5: North | E5: Electronics | F5: Printer | G5: 2 | H5: 481.29 | I5: 962.58 | J5: =IF('Main Data'!I5>=5000,"High", "Low") -> Low | K5: =YEAR(B5) -> 2023 | L5: =PROPER(C5) -> William Morgan | M5: =UPPER(C5) -> WILLIAM MORGAN | N5: =G5*(H5*0.9) -> 866.322 | O5: =TEXT((B5),"mmm-yyyy") -> Apr-2023 | P5: =I5*18% -> 173.2644 | Q5: =CONCATENATE(F5," ",E5) -> Printer Electronics | R5: =IF('sales data'!I5<3000,"Low",IF('sales data'!I5<7999, "Medium","High")) -> Low | S5: =IF(A5=_xlfn.MINIFS($A$3:$A$1001, $B$2:$B$1000, B5), "First Timer", "Regular") -> Regular | T5: =AVERAGE(I3,I4,I5) -> 1250.9167 | V5: Chair | W5: 36334.48
A6: 4451 | B6: 45025 | C6: Mr. Dakota Owens | D6: East | E6: Furniture | F6: Monitor | G6: 1 | H6: 661.87 | I6: 661.87 | J6: =IF('Main Data'!I6>=5000,"High", "Low") -> Low | K6: =YEAR(B6) -> 2023 | L6: =PROPER(C6) -> Mr. Dakota Owens | M6: =UPPER(C6) -> MR. DAKOTA OWENS | N6: =G6*(H6*0.9) -> 595.683 | O6: =TEXT((B6),"mmm-yyyy") -> Apr-2023 | P6: =I6*18% -> 119.1366 | Q6: =CONCATENATE(F6," ",E6) -> Monitor Furniture | R6: =IF('sales data'!I6<3000,"Low",IF('sales data'!I6<7999, "Medium","High")) -> Low | S6: =IF(A6=_xlfn.MINIFS($A$3:$A$1001, $B$2:$B$1000, B6), "First Timer", "Regular") -> Regular | T6: =AVERAGE(I4,I5,I6) -> 811.94 | V6: Desk | W6: 19929.95
A7: 5863 | B7: 45025 | C7: William Barber DDS | D7: North | E7: Office Supplies | F7: Desk | G7: 4 | H7: 377.33 | I7: 1509.32 | J7: =IF('Main Data'!I7>=5000,"High", "Low") -> Low | K7: =YEAR(B7) -> 2023 | L7: =PROPER(C7) -> William Barber Dds | M7: =UPPER(C7) -> WILLIAM BARBER DDS | N7: =G7*(H7*0.9) -> 1358.388 | O7: =TEXT((B7),"mmm-yyyy") -> Apr-2023 | P7: =I7*18% -> 271.6776 | Q7: =CONCATENATE(F7," ",E7) -> Desk Office Supplies | R7: =IF('sales data'!I7<3000,"Low",IF('sales data'!I7<7999, "Medium","High")) -> Low | S7: =IF(A7=_xlfn.MINIFS($A$3:$A$1001, $B$2:$B$1000, B7), "First Timer", "Regular") -> Regular | T7: =AVERAGE(I5,I6,I7) -> 1044.59 | V7: Laptop | W7: 12359.64
A8: 2915 | B8: 45025 | C8: Robert Mack | D8: South | E8: Furniture | F8: Notebook | G8: 8 | H8: 869.46 | I8: 6955.68 | J8: =IF('Main Data'!I8>=5000,"High", "Low") -> High | K8: =YEAR(B8) -> 2023 | L8: =PROPER(C8) -> Robert Mack | M8: =UPPER(C8) -> ROBERT MACK | N8: =G8*(H8*0.9) -> 6260.112 | O8: =TEXT((B8),"mmm-yyyy") -> Apr-2023 | P8: =I8*18% -> 1252.0224 | Q8: =CONCATENATE(F8," ",E8) -> Notebook Furniture | R8: =IF('sales data'!I8<3000,"Low",IF('sales data'!I8<7999, "Medium","High")) -> Medium | S8: =IF(A8=_xlfn.MINIFS($A$3:$A$1001, $B$2:$B$1000, B8), "First Timer", "Regular") -> Regular | T8: =AVERAGE(I6,I7,I8) -> 3042.29 | V8: Monitor | W8: 33280.59
A9: 2315 | B9: 45026 | C9: David Greene | D9: South | E9: Electronics | F9: Chair | G9: 1 | H9: 983.84 | I9: 983.84 | J9: =IF('Main Data'!I9>=5000,"High", "Low") -> Low | K9: =YEAR(B9) -> 2023 | L9: =PROPER(C9) -> David Greene | M9: =UPPER(C9) -> DAVID GREENE | N9: =G9*(H9*0.9) -> 885.456 | O9: =TEXT((B9),"mmm-yyyy") -> Apr-2023 | P9: =I9*18% -> 177.0912 | Q9: =CONCATENATE(F9," ",E9) -> Chair Electronics | R9: =IF('sales data'!I9<3000,"Low",IF('sales data'!I9<7999, "Medium","High")) -> Low | S9: =IF(A9=_xlfn.MINIFS($A$3:$A$1001, $B$2:$B$1000, B9), "First Timer", "Regular") -> Regular | T9: =AVERAGE(I7,I8,I9) -> 3149.6133 | V9: Notebook | W9: 24906.82
A10: 7129 | B10: 45027 | C10: Janice Hammond | D10: East | E10: Electronics | F10: Chair | G10: 1 | H10: 115.53 | I10: 115.53 | J10: =IF('Main Data'!I10>=5000,"High", "Low") -> Low | K10: =YEAR(B10) -> 2023 | L10: =PROPER(C10) -> Janice Hammond | M10: =UPPER(C10) -> JANICE HAMMOND | N10: =G10*(H10*0.9) -> 103.977 | O10: =TEXT((B10),"mmm-yyyy") -> Apr-2023 | P10: =I10*18% -> 20.7954 | Q10: =CONCATENATE(F10," ",E10) -> Chair Electronics | R10: =IF('sales data'!I10<3000,"Low",IF('sales data'!I10<7999, "Medium","High")) -> Low | S10: =IF(A10=_xlfn.MINIFS($A$3:$A$1001, $B$2:$B$1000, B10), "First Timer", "Regular") -> Regular | T10: =AVERAGE(I8,I9,I10) -> 2685.0167 | V10: Pen | W10: 24099.86
A11: 1822 | B11: 45029 | C11: Daniel Griffin Jr. | D11: North | E11: Office Supplies | F11: Notebook | G11: 8 | H11: 925.15 | I11: 7401.2 | J11: =IF('Main Data'!I11>=5000,"High", "Low") -> High | K11: =YEAR(B11) -> 2023 | L11: =PROPER(C11) -> Daniel Griffin Jr. | M11: =UPPER(C11) -> DANIEL GRIFFIN JR. | N11: =G11*(H11*0.9) -> 6661.08 | O11: =TEXT((B11),"mmm-yyyy") -> Apr-2023 | P11: =I11*18% -> 1332.216 | Q11: =CONCATENATE(F11," ",E11) -> Notebook Office Supplies | R11: =IF('sales data'!I11<3000,"Low",IF('sales data'!I11<7999, "Medium","High")) -> Medium | S11: =IF(A11=_xlfn.MINIFS($A$3:$A$1001, $B$2:$B$1000, B11), "First Timer", "Regular") -> Regular | T11: =AVERAGE(I9,I10,I11) -> 2833.5233 | V11: Printer | W11: 21972.38
A12: 2951 | B12: 45029 | C12: Sara Harrison | D12: West | E12: Office Supplies | F12: Chair | G12: 6 | H12: 357.2 | I12: 2143.2 | J12: =IF('Main Data'!I12>=5000,"High", "Low") -> Low | K12: =YEAR(B12) -> 2023 | L12: =PROPER(C12) -> Sara Harrison | M12: =UPPER(C12) -> SARA HARRISON | N12: =G12*(H12*0.9) -> 1928.88 | O12: =TEXT((B12),"mmm-yyyy") -> Apr-2023 | P12: =I12*18% -> 385.776 | Q12: =CONCATENATE(F12," ",E12) -> Chair Office Supplies | R12: =IF('sales data'!I12<3000,"Low",IF('sales data'!I12<7999, "Medium","High")) -> Low | S12: =IF(A12=_xlfn.MINIFS($A$3:$A$1001, $B$2:$B$1000, B12), "First Timer", "Regular") -> First Timer | T12: =AVERAGE(I10,I11,I12) -> 3219.9767 | V12: Table | W12: 38475.39
A13: 6869 | B13: 45029 | C13: Kathleen King | D13: South | E13: Furniture | F13: Laptop | G13: 6 | H13: 782.95 | I13: 4697.7 | J13: =IF('Main Data'!I13>=5000,"High", "Low") -> Low | K13: =YEAR(B13) -> 2023 | L13: =PROPER(C13) -> Kathleen King | M13: =UPPER(C13) -> KATHLEEN KING | N13: =G13*(H13*0.9) -> 4227.93 | O13: =TEXT((B13),"mmm-yyyy") -> Apr-2023 | P13: =I13*18% -> 845.586 | Q13: =CONCATENATE(F13," ",E13) -> Laptop Furniture | R13: =IF('sales data'!I13<3000,"Low",IF('sales data'!I13<7999, "Medium","High")) -> Medium | S13: =IF(A13=_xlfn.MINIFS($A$3:$A$1001, $B$2:$B$1000, B13), "First Timer", "Regular") -> Regular | T13: =AVERAGE(I11,I12,I13) -> 4747.3667 | V13: Furniture | W13: 199728.57
A14: 6012 | B14: 45031 | C14: Charles Stokes | D14: West | E14: Electronics | F14: Laptop | G14: 4 | H14: 421.99 | I14: 1687.96 | J14: =IF('Main Data'!I14>=5000,"High", "Low") -> Low | K14: =YEAR(B14) -> 2023 | L14: =PROPER(C14) -> Charles Stokes | M14: =UPPER(C14) -> CHARLES STOKES | N14: =G14*(H14*0.9) -> 1519.164 | O14: =TEXT((B14),"mmm-yyyy") -> Apr-2023 | P14: =I14*18% -> 303.8328 | Q14: =CONCATENATE(F14," ",E14) -> Laptop Electronics | R14: =IF('sales data'!I14<3000,"Low",IF('sales data'!I14<7999, "Medium","High")) -> Low | S14: =IF(A14=_xlfn.MINIFS($A$3:$A$1001, $B$2:$B$1000, B14), "First Timer", "Regular") -> Regular | T14: =AVERAGE(I12,I13,I14) -> 2842.9533 | V14: Chair | W14: 27970.09
A15: 2481 | B15: 45032 | C15: Terry Fisher | D15: West | E15: Furniture | F15: Monitor | G15: 2 | H15: 880.33 | I15: 1760.66 | J15: =IF('Main Data'!I15>=5000,"High", "Low") -> Low | K15: =YEAR(B15) -> 2023 | L15: =PROPER(C15) -> Terry Fisher | M15: =UPPER(C15) -> TERRY FISHER | N15: =G15*(H15*0.9) -> 1584.594 | O15: =TEXT((B15),"mmm-yyyy") -> Apr-2023 | P15: =I15*18% -> 316.9188 | Q15: =CONCATENATE(F15," ",E15) -> Monitor Furniture | R15: =IF('sales data'!I15<3000,"Low",IF('sales data'!I15<7999, "Medium","High")) -> Low | S15: =IF(A15=_xlfn.MINIFS($A$3:$A$1001, $B$2:$B$1000, B15), "First Timer", "Regular") -> Regular | T15: =AVERAGE(I13,I14,I15) -> 2715.44 | V15: Desk | W15: 7971.73
... A115: 1541 | B115: 45104 | C115: Brooke Garrett | D115: North | E115: Furniture | F115: Laptop | G115: 7 | H115: 846.34 | I115: 5924.38 | J115: =IF('Main Data'!I115>=5000,"High", "Low") -> High | K115: =YEAR(B115) -> 2023 | L115: =PROPER(C115) -> Brooke Garrett | M115: =UPPER(C115) -> BROOKE GARRETT | N115: =G115*(H115*0.9) -> 5331.942 | O115: =TEXT((B115),"mmm-yyyy") -> Jun-2023 | P115: =I115*18% -> 1066.3884 | Q115: =CONCATENATE(F115," ",E115) -> Laptop Furniture | R115: =IF('sales data'!I115<3000,"Low",IF('sales data'!I115<7999, "Medium","High")) -> Medium | S115: =IF(A115=_xlfn.MINIFS($A$3:$A$1001, $B$2:$B$1000, B115), "First Timer", "Regular") -> Regular | T115: =AVERAGE(I113,I114,I115) -> 4553.9533 | V115: Grand Total | W115: 2469040.4
A116: 5251 | B116: 45104 | C116: Tommy Leonard | D116: East | E116: Furniture | F116: Desk | G116: 7 | H116: 218.56 | I116: 1529.92 | J116: =IF('Main Data'!I116>=5000,"High", "Low") -> Low | K116: =YEAR(B116) -> 2023 | L116: =PROPER(C116) -> Tommy Leonard | M116: =UPPER(C116) -> TOMMY LEONARD | N116: =G116*(H116*0.9) -> 1376.928 | O116: =TEXT((B116),"mmm-yyyy") -> Jun-2023 | P116: =I116*18% -> 275.3856 | Q116: =CONCATENATE(F116," ",E116) -> Desk Furniture | R116: =IF('sales data'!I116<3000,"Low",IF('sales data'!I116<7999, "Medium","High")) -> Low | S116: =IF(A116=_xlfn.MINIFS($A$3:$A$1001, $B$2:$B$1000, B116), "First Timer", "Regular") -> Regular | T116: =AVERAGE(I114,I115,I116) -> 4421.7867
A117: 5204 | B117: 45104 | C117: Jeffrey Miller | D117: East | E117: Furniture | F117: Printer | G117: 9 | H117: 869.59 | I117: 7826.31 | J117: =IF('Main Data'!I117>=5000,"High", "Low") -> High | K117: =YEAR(B117) -> 2023 | L117: =PROPER(C117) -> Jeffrey Miller | M117: =UPPER(C117) -> JEFFREY MILLER | N117: =G117*(H117*0.9) -> 7043.679 | O117: =TEXT((B117),"mmm-yyyy") -> Jun-2023 | P117: =I117*18% -> 1408.7358 | Q117: =CONCATENATE(F117," ",E117) -> Printer Furniture | R117: =IF('sales data'!I117<3000,"Low",IF('sales data'!I117<7999, "Medium","High")) -> Medium | S117: =IF(A117=_xlfn.MINIFS($A$3:$A$1001, $B$2:$B$1000, B117), "First Timer", "Regular") -> Regular | T117: =AVERAGE(I115,I116,I117) -> 5093.5367
A118: 3188 | B118: 45104 | C118: Timothy Thomas | D118: South | E118: Furniture | F118: Monitor | G118: 9 | H118: 544.61 | I118: 4901.49 | J118: =IF('Main Data'!I118>=5000,"High", "Low") -> Low | K118: =YEAR(B118) -> 2023 | L118: =PROPER(C118) -> Timothy Thomas | M118: =UPPER(C118) -> TIMOTHY THOMAS | N118: =G118*(H118*0.9) -> 4411.341 | O118: =TEXT((B118),"mmm-yyyy") -> Jun-2023 | P118: =I118*18% -> 882.2682 | Q118: =CONCATENATE(F118," ",E118) -> Monitor Furniture | R118: =IF('sales data'!I118<3000,"Low",IF('sales data'!I118<7999, "Medium","High")) -> Medium | S118: =IF(A118=_xlfn.MINIFS($A$3:$A$1001, $B$2:$B$1000, B118), "First Timer", "Regular") -> First Timer | T118: =AVERAGE(I116,I117,I118) -> 4752.5733
A119: 6693 | B119: 45106 | C119: Carol Guerra | D119: North | E119: Furniture | F119: Laptop | G119: 7 | H119: 937.46 | I119: 6562.22 | J119: =IF('Main Data'!I119>=5000,"High", "Low") -> High | K119: =YEAR(B119) -> 2023 | L119: =PROPER(C119) -> Carol Guerra | M119: =UPPER(C119) -> CAROL GUERRA | N119: =G119*(H119*0.9) -> 5905.998 | O119: =TEXT((B119),"mmm-yyyy") -> Jun-2023 | P119: =I119*18% -> 1181.1996 | Q119: =CONCATENATE(F119," ",E119) -> Laptop Furniture | R119: =IF('sales data'!I119<3000,"Low",IF('sales data'!I119<7999, "Medium","High")) -> Medium | S119: =IF(A119=_xlfn.MINIFS($A$3:$A$1001, $B$2:$B$1000, B119), "First Timer", "Regular") -> Regular | T119: =AVERAGE(I117,I118,I119) -> 6430.0067
A120: 8692 | B120: 45107 | C120: Kimberly Ballard | D120: West | E120: Electronics | F120: Pen | G120: 4 | H120: 246.39 | I120: 985.56 | J120: =IF('Main Data'!I120>=5000,"High", "Low") -> Low | K120: =YEAR(B120) -> 2023 | L120: =PROPER(C120) -> Kimberly Ballard | M120: =UPPER(C120) -> KIMBERLY BALLARD | N120: =G120*(H120*0.9) -> 887.004 | O120: =TEXT((B120),"mmm-yyyy") -> Jun-2023 | P120: =I120*18% -> 177.4008 | Q120: =CONCATENATE(F120," ",E120) -> Pen Electronics | R120: =IF('sales data'!I120<3000,"Low",IF('sales data'!I120<7999, "Medium","High")) -> Low | S120: =IF(A120=_xlfn.MINIFS($A$3:$A$1001, $B$2:$B$1000, B120), "First Timer", "Regular") -> Regular | T120: =AVERAGE(I118,I119,I120) -> 4149.7567
A121: 4482 | B121: 45107 | C121: Frank Thomas | D121: West | E121: Office Supplies | F121: Table | G121: 2 | H121: 735.78 | I121: 1471.56 | J121: =IF('Main Data'!I121>=5000,"High", "Low") -> Low | K121: =YEAR(B121) -> 2023 | L121: =PROPER(C121) -> Frank Thomas | M121: =UPPER(C121) -> FRANK THOMAS | N121: =G121*(H121*0.9) -> 1324.404 | O121: =TEXT((B121),"mmm-yyyy") -> Jun-2023 | P121: =I121*18% -> 264.8808 | Q121: =CONCATENATE(F121," ",E121) -> Table Office Supplies | R121: =IF('sales data'!I121<3000,"Low",IF('sales data'!I121<7999, "Medium","High")) -> Low | S121: =IF(A121=_xlfn.MINIFS($A$3:$A$1001, $B$2:$B$1000, B121), "First Timer", "Regular") -> Regular | T121: =AVERAGE(I119,I120,I121) -> 3006.4467
A122: 4174 | B122: 45108 | C122: Erica Russell | D122: North | E122: Electronics | F122: Printer | G122: 7 | H122: 556.53 | I122: 3895.71 | J122: =IF('Main Data'!I122>=5000,"High", "Low") -> Low | K122: =YEAR(B122) -> 2023 | L122: =PROPER(C122) -> Erica Russell | M122: =UPPER(C122) -> ERICA RUSSELL | N122: =G122*(H122*0.9) -> 3506.139 | O122: =TEXT((B122),"mmm-yyyy") -> Jul-2023 | P122: =I122*18% -> 701.2278 | Q122: =CONCATENATE(F122," ",E122) -> Printer Electronics | R122: =IF('sales data'!I122<3000,"Low",IF('sales data'!I122<7999, "Medium","High")) -> Medium | S122: =IF(A122=_xlfn.MINIFS($A$3:$A$1001, $B$2:$B$1000, B122), "First Timer", "Regular") -> Regular | T122: =AVERAGE(I120,I121,I122) -> 2117.61
A123: 4577 | B123: 45109 | C123: Kimberly Curtis | D123: North | E123: Electronics | F123: Laptop | G123: 2 | H123: 637.14 | I123: 1274.28 | J123: =IF('Main Data'!I123>=5000,"High", "Low") -> Low | K123: =YEAR(B123) -> 2023 | L123: =PROPER(C123) -> Kimberly Curtis | M123: =UPPER(C123) -> KIMBERLY CURTIS | N123: =G123*(H123*0.9) -> 1146.852 | O123: =TEXT((B123),"mmm-yyyy") -> Jul-2023 | P123: =I123*18% -> 229.3704 | Q123: =CONCATENATE(F123," ",E123) -> Laptop Electronics | R123: =IF('sales data'!I123<3000,"Low",IF('sales data'!I123<7999, "Medium","High")) -> Low | S123: =IF(A123=_xlfn.MINIFS($A$3:$A$1001, $B$2:$B$1000, B123), "First Timer", "Regular") -> Regular | T123: =AVERAGE(I121,I122,I123) -> 2213.85
A124: 7008 | B124: 45109 | C124: Alyssa Jackson | D124: North | E124: Office Supplies | F124: Chair | G124: 2 | H124: 485.7 | I124: 971.4 | J124: =IF('Main Data'!I124>=5000,"High", "Low") -> Low | K124: =YEAR(B124) -> 2023 | L124: =PROPER(C124) -> Alyssa Jackson | M124: =UPPER(C124) -> ALYSSA JACKSON | N124: =G124*(H124*0.9) -> 874.26 | O124: =TEXT((B124),"mmm-yyyy") -> Jul-2023 | P124: =I124*18% -> 174.852 | Q124: =CONCATENATE(F124," ",E124) -> Chair Office Supplies | R124: =IF('sales data'!I124<3000,"Low",IF('sales data'!I124<7999, "Medium","High")) -> Low | S124: =IF(A124=_xlfn.MINIFS($A$3:$A$1001, $B$2:$B$1000, B124), "First Timer", "Regular") -> Regular | T124: =AVERAGE(I122,I123,I124) -> 2047.13
A125: 8506 | B125: 45109 | C125: George Taylor | D125: East | E125: Office Supplies | F125: Laptop | G125: 4 | H125: 975.05 | I125: 3900.2 | J125: =IF('Main Data'!I125>=5000,"High", "Low") -> Low | K125: =YEAR(B125) -> 2023 | L125: =PROPER(C125) -> George Taylor | M125: =UPPER(C125) -> GEORGE TAYLOR | N125: =G125*(H125*0.9) -> 3510.18 | O125: =TEXT((B125),"mmm-yyyy") -> Jul-2023 | P125: =I125*18% -> 702.036 | Q125: =CONCATENATE(F125," ",E125) -> Laptop Office Supplies | R125: =IF('sales data'!I125<3000,"Low",IF('sales data'!I125<7999, "Medium","High")) -> Medium | S125: =IF(A125=_xlfn.MINIFS($A$3:$A$1001, $B$2:$B$1000, B125), "First Timer", "Regular") -> Regular | T125: =AVERAGE(I123,I124,I125) -> 2048.6267
A126: 5158 | B126: 45109 | C126: Michele Thomas | D126: East | E126: Electronics | F126: Laptop | G126: 1 | H126: 385.99 | I126: 385.99 | J126: =IF('Main Data'!I126>=5000,"High", "Low") -> Low | K126: =YEAR(B126) -> 2023 | L126: =PROPER(C126) -> Michele Thomas | M126: =UPPER(C126) -> MICHELE THOMAS | N126: =G126*(H126*0.9) -> 347.391 | O126: =TEXT((B126),"mmm-yyyy") -> Jul-2023 | P126: =I126*18% -> 69.4782 | Q126: =CONCATENATE(F126," ",E126) -> Laptop Electronics | R126: =IF('sales data'!I126<3000,"Low",IF('sales data'!I126<7999, "Medium","High")) -> Low | S126: =IF(A126=_xlfn.MINIFS($A$3:$A$1001, $B$2:$B$1000, B126), "First Timer", "Regular") -> First Timer | T126: =AVERAGE(I124,I125,I126) -> 1752.53
A127: 6131 | B127: 45110 | C127: Michael Adams | D127: South | E127: Electronics | F127: Desk | G127: 5 | H127: 108.45 | I127: 542.25 | J127: =IF('Main Data'!I127>=5000,"High", "Low") -> Low | K127: =YEAR(B127) -> 2023 | L127: =PROPER(C127) -> Michael Adams | M127: =UPPER(C127) -> MICHAEL ADAMS | N127: =G127*(H127*0.9) -> 488.025 | O127: =TEXT((B127),"mmm-yyyy") -> Jul-2023 | P127: =I127*18% -> 97.605 | Q127: =CONCATENATE(F127," ",E127) -> Desk Electronics | R127: =IF('sales data'!I127<3000,"Low",IF('sales data'!I127<7999, "Medium","High")) -> Low | S127: =IF(A127=_xlfn.MINIFS($A$3:$A$1001, $B$2:$B$1000, B127), "First Timer", "Regular") -> Regular | T127: =AVERAGE(I125,I126,I127) -> 1609.48
... A1001: 3344 | B1001: 45751 | C1001: Taylor Lowe | D1001: North | E1001: Furniture | F1001: Notebook | G1001: 2 | H1001: 757.49 | I1001: 1514.98 | J1001: =IF('Main Data'!I1001>=5000,"High", "Low") -> Low | K1001: =YEAR(B1001) -> 2025 | L1001: =PROPER(C1001) -> Taylor Lowe | M1001: =UPPER(C1001) -> TAYLOR LOWE | N1001: =G1001*(H1001*0.9) -> 1363.482 | O1001: =TEXT((B1001),"mmm-yyyy") -> Apr-2025 | P1001: =I1001*18% -> 272.6964 | Q1001: =CONCATENATE(F1001," ",E1001) -> Notebook Furniture | R1001: =IF('sales data'!I1001<3000,"Low",IF('sales data'!I1001<7999, "Medium","High")) -> Low | S1001: =IF(A1001=_xlfn.MINIFS($A$3:$A$1001, $B$2:$B$1000, B1001), "First Timer", "Regular") -> Regular | T1001: =AVERAGE(I999,I1000,I1001) -> 2925.4

Sheet dynamic chart
B1: Details for Sum of Order ID
A3: Region | B3: Order ID | C3: Order Date | D3: Customer Name | E3: Product Category | F3: Product Name | G3: Quantity | H3: Unit Price | I3: Total Sales | J3: Sales Type | K3: year | L3: DISCOUNTED PRICE | M3: SALES TAX 18% | O3: Region | P3: South
A4: West | B4: 1009 | C4: 45729 | D4: Nicole Graves | E4: Office Supplies | F4: Monitor | G4: 8 | H4: 857.14 | I4: 6857.12 | J4: High | K4: 2025 | L4: 6171.408 | M4: 1234.2816 | O4: Order ID | P4: Order Date | Q4: Customer Name | R4: Product Category | S4: Product Name | T4: Quantity | U4: Unit Price | V4: Total Sales | W4: Sales Type | X4: year | Y4: DISCOUNTED PRICE | Z4: SALES TAX 18%
A5: North | B5: 1010 | C5: 45564 | D5: Ashley James | E5: Electronics | F5: Desk | G5: 9 | H5: 130.17 | I5: 1171.53 | J5: Low | K5: 2024 | L5: 1054.377 | M5: 210.8754 | O5: {=_xlfn._xlws.FILTER(Table1[[Order ID]:[SALES TAX 18%]],Table1[Region]=Region)} -> 1287 | P5: 45061 | Q5: Christina Taylor | R5: Office Supplies | S5: Monitor | T5: 4 | U5: 555.35 | V5: 2221.4 | W5: Low | X5: 2023 | Y5: 1999.26 | Z5: 399.852 | AF5: .
A6: West | B6: 1032 | C6: 45445 | D6: James Buchanan | E6: Furniture | F6: Laptop | G6: 3 | H6: 963.3 | I6: 2889.9 | J6: Low | K6: 2024 | L6: 2600.91 | M6: 520.182 | O6: 1307 | P6: 45097 | Q6: Melinda Fernandez | R6: Furniture | S6: Printer | T6: 6 | U6: 31.06 | V6: 186.36 | W6: Low | X6: 2023 | Y6: 167.724 | Z6: 33.5448
A7: West | B7: 1038 | C7: 45631 | D7: Briana Fry | E7: Office Supplies | F7: Laptop | G7: 5 | H7: 611.66 | I7: 3058.3 | J7: Low | K7: 2024 | L7: 2752.47 | M7: 550.494 | O7: 1319 | P7: 45366 | Q7: Nathan Cruz | R7: Furniture | S7: Printer | T7: 8 | U7: 14.89 | V7: 119.12 | W7: Low | X7: 2024 | Y7: 107.208 | Z7: 21.4416
A8: East | B8: 1042 | C8: 45388 | D8: Darren Watson | E8: Electronics | F8: Monitor | G8: 6 | H8: 889.86 | I8: 5339.16 | J8: High | K8: 2024 | L8: 4805.244 | M8: 961.0488 | O8: 1321 | P8: 45174 | Q8: Susan Graves | R8: Office Supplies | S8: Notebook | T8: 9 | U8: 745.28 | V8: 6707.52 | W8: High | X8: 2023 | Y8: 6036.768 | Z8: 1207.3536
A9: East | B9: 1055 | C9: 45727 | D9: Daniel Wagner | E9: Furniture | F9: Desk | G9: 8 | H9: 265.31 | I9: 2122.48 | J9: Low | K9: 2025 | L9: 1910.232 | M9: 382.0464 | O9: 1336 | P9: 45321 | Q9: Elizabeth Pugh | R9: Electronics | S9: Printer | T9: 8 | U9: 824.39 | V9: 6595.12 | W9: High | X9: 2024 | Y9: 5935.608 | Z9: 1187.1216
A10: East | B10: 1062 | C10: 45246 | D10: Katrina Mcmahon | E10: Furniture | F10: Chair | G10: 1 | H10: 174.62 | I10: 174.62 | J10: Low | K10: 2023 | L10: 157.158 | M10: 31.4316 | O10: 1344 | P10: 45560 | Q10: Dennis Stevens | R10: Office Supplies | S10: Monitor | T10: 4 | U10: 497.36 | V10: 1989.44 | W10: Low | X10: 2024 | Y10: 1790.496 | Z10: 358.0992
A11: East | B11: 1063 | C11: 45343 | D11: Nancy Chapman DDS | E11: Electronics | F11: Pen | G11: 2 | H11: 647.14 | I11: 1294.28 | J11: Low | K11: 2024 | L11: 1164.852 | M11: 232.9704 | O11: 1375 | P11: 45246 | Q11: Eric Walker | R11: Electronics | S11: Laptop | T11: 5 | U11: 872.26 | V11: 4361.3 | W11: Low | X11: 2023 | Y11: 3925.17 | Z11: 785.034
A12: East | B12: 1079 | C12: 45444 | D12: Marco Jones | E12: Office Supplies | F12: Chair | G12: 3 | H12: 895.25 | I12: 2685.75 | J12: Low | K12: 2024 | L12: 2417.175 | M12: 483.435 | O12: 1392 | P12: 45386 | Q12: Nicole Armstrong | R12: Office Supplies | S12: Monitor | T12: 1 | U12: 596.43 | V12: 596.43 | W12: Low | X12: 2024 | Y12: 536.787 | Z12: 107.3574
A13: East | B13: 1083 | C13: 45330 | D13: Andrew White | E13: Office Supplies | F13: Desk | G13: 1 | H13: 846.1 | I13: 846.1 | J13: Low | K13: 2024 | L13: 761.49 | M13: 152.298 | O13: 1556 | P13: 45516 | Q13: Lisa Joseph | R13: Office Supplies | S13: Laptop | T13: 9 | U13: 665.22 | V13: 5986.98 | W13: High | X13: 2024 | Y13: 5388.282 | Z13: 1077.6564
A14: East | B14: 1088 | C14: 45478 | D14: Mrs. Cassandra Larson MD | E14: Office Supplies | F14: Pen | G14: 7 | H14: 221.38 | I14: 1549.66 | J14: Low | K14: 2024 | L14: 1394.694 | M14: 278.9388 | O14: 1586 | P14: 45111 | Q14: Anthony Castillo | R14: Office Supplies | S14: Pen | T14: 4 | U14: 819.27 | V14: 3277.08 | W14: Low | X14: 2023 | Y14: 2949.372 | Z14: 589.8744
A15: West | B15: 1093 | C15: 45593 | D15: Alvin Santiago | E15: Office Supplies | F15: Desk | G15: 3 | H15: 236.17 | I15: 708.51 | J15: Low | K15: 2024 | L15: 637.659 | M15: 127.5318 | O15: 1592 | P15: 45311 | Q15: Jennifer Frost | R15: Furniture | S15: Monitor | T15: 1 | U15: 256.23 | V15: 256.23 | W15: Low | X15: 2024 | Y15: 230.607 | Z15: 46.1214
A16: West | B16: 1095 | C16: 45386 | D16: Mark Houston | E16: Electronics | F16: Chair | G16: 9 | H16: 931.64 | I16: 8384.76 | J16: High | K16: 2024 | L16: 7546.284 | M16: 1509.2568 | O16: 1607 | P16: 45138 | Q16: Jennifer Hahn | R16: Furniture | S16: Desk | T16: 7 | U16: 969.72 | V16: 6788.04 | W16: High | X16: 2023 | Y16: 6109.236 | Z16: 1221.8472
A17: East | B17: 1104 | C17: 45458 | D17: Emma Mendoza | E17: Office Supplies | F17: Notebook | G17: 7 | H17: 500.2 | I17: 3501.4 | J17: Low | K17: 2024 | L17: 3151.26 | M17: 630.252 | O17: 1619 | P17: 45297 | Q17: Michelle Wilkinson | R17: Furniture | S17: Notebook | T17: 5 | U17: 554.03 | V17: 2770.15 | W17: Low | X17: 2024 | Y17: 2493.135 | Z17: 498.627
... A258: South | B258: 3315 | C258: 45686 | D258: Kara Walsh | E258: Electronics | F258: Printer | G258: 8 | H258: 232.2 | I258: 1857.6 | J258: Low | K258: 2025 | L258: 1671.84 | M258: 334.368 | O258: 9976 | P258: 45246 | Q258: Timothy Ramirez | R258: Office Supplies | S258: Pen | T258: 7 | U258: 540.47 | V258: 3783.29 | W258: Low | X258: 2023 | Y258: 3404.961 | Z258: 680.9922
A259: East | B259: 3325 | C259: 45072 | D259: Justin Sheppard | E259: Electronics | F259: Laptop | G259: 9 | H259: 419.41 | I259: 3774.69 | J259: Low | K259: 2023 | L259: 3397.221 | M259: 679.4442
A260: South | B260: 3328 | C260: 45023 | D260: Wesley Davis | E260: Furniture | F260: Chair | G260: 3 | H260: 659.6 | I260: 1978.8 | J260: Low | K260: 2023 | L260: 1780.92 | M260: 356.184
A261: North | B261: 3344 | C261: 45751 | D261: Taylor Lowe | E261: Furniture | F261: Notebook | G261: 2 | H261: 757.49 | I261: 1514.98 | J261: Low | K261: 2025 | L261: 1363.482 | M261: 272.6964
A262: East | B262: 3356 | C262: 45057 | D262: Erin Moore | E262: Office Supplies | F262: Monitor | G262: 1 | H262: 96.99 | I262: 96.99 | J262: Low | K262: 2023 | L262: 87.291 | M262: 17.4582
A263: South | B263: 3364 | C263: 45233 | D263: Gary Jenkins | E263: Electronics | F263: Chair | G263: 7 | H263: 67.58 | I263: 473.06 | J263: Low | K263: 2023 | L263: 425.754 | M263: 85.1508
A264: East | B264: 3414 | C264: 45378 | D264: David Miller | E264: Electronics | F264: Table | G264: 5 | H264: 456.87 | I264: 2284.35 | J264: Low | K264: 2024 | L264: 2055.915 | M264: 411.183
A265: North | B265: 3422 | C265: 45221 | D265: Steven Moran | E265: Office Supplies | F265: Chair | G265: 2 | H265: 449.31 | I265: 898.62 | J265: Low | K265: 2023 | L265: 808.758 | M265: 161.7516
A266: East | B266: 3427 | C266: 45112 | D266: Richard Taylor | E266: Office Supplies | F266: Monitor | G266: 6 | H266: 48.95 | I266: 293.7 | J266: Low | K266: 2023 | L266: 264.33 | M266: 52.866
A267: East | B267: 3428 | C267: 45697 | D267: Gregory Jones | E267: Furniture | F267: Table | G267: 2 | H267: 952.29 | I267: 1904.58 | J267: Low | K267: 2025 | L267: 1714.122 | M267: 342.8244
A268: East | B268: 3434 | C268: 45281 | D268: Keith Gaines | E268: Electronics | F268: Table | G268: 4 | H268: 314.85 | I268: 1259.4 | J268: Low | K268: 2023 | L268: 1133.46 | M268: 226.692
A269: West | B269: 3437 | C269: 45235 | D269: Jennifer Brown | E269: Electronics | F269: Notebook | G269: 9 | H269: 493.76 | I269: 4443.84 | J269: Low | K269: 2023 | L269: 3999.456 | M269: 799.8912
A270: East | B270: 3448 | C270: 45189 | D270: Amy Anderson | E270: Electronics | F270: Table | G270: 1 | H270: 104.58 | I270: 104.58 | J270: Low | K270: 2023 | L270: 94.122 | M270: 18.8244
... A1003: East | B1003: 9993 | C1003: 45507 | D1003: John Taylor | E1003: Office Supplies | F1003: Laptop | G1003: 9 | H1003: 199.95 | I1003: 1799.55 | J1003: Low | K1003: 2024 | L1003: 1619.595 | M1003: 323.919

Sheet Product_Lookup Data
A1: Product Name | B1: Product ID | C1: Supplier | D1: Stock Available | E1: Rating | G1: Left | H1: Right | I1: Mid
A2: Laptop | B2: P100 | C2: Turner LLC | D2: 38 | E2: 3.5 | G2: =LEFT(B2,2) -> P1 | H2: =RIGHT(B2,2) -> 00 | I2: =MID(B2,2,3) -> 100
A3: Chair | B3: P101 | C3: Shelton PLC | D3: 39 | E3: 4.5 | G3: =LEFT(B3,2) -> P1 | H3: =RIGHT(B3,2) -> 01 | I3: =MID(B3,2,3) -> 101
A4: Desk | B4: P102 | C4: Peters-Bell | D4: 48 | E4: 5 | G4: =LEFT(B4,2) -> P1 | H4: =RIGHT(B4,2) -> 02 | I4: =MID(B4,2,3) -> 102
A5: Monitor | B5: P103 | C5: Murray, Gray and Mitchell | D5: 34 | E5: 3.2 | G5: =LEFT(B5,2) -> P1 | H5: =RIGHT(B5,2) -> 03 | I5: =MID(B5,2,3) -> 103
A6: Printer | B6: P104 | C6: Gutierrez LLC | D6: 17 | E6: 3.8 | G6: =LEFT(B6,2) -> P1 | H6: =RIGHT(B6,2) -> 04 | I6: =MID(B6,2,3) -> 104
A7: Pen | B7: P105 | C7: Mcfarland-Jimenez | D7: 67 | E7: 4.6 | G7: =LEFT(B7,2) -> P1 | H7: =RIGHT(B7,2) -> 05 | I7: =MID(B7,2,3) -> 105
A8: Notebook | B8: P106 | C8: Weeks and Sons | D8: 25 | E8: 3.4 | G8: =LEFT(B8,2) -> P1 | H8: =RIGHT(B8,2) -> 06 | I8: =MID(B8,2,3) -> 106
A9: Table | B9: P107 | C9: Cohen Ltd | D9: 81 | E9: 4.1 | G9: =LEFT(B9,2) -> P1 | H9: =RIGHT(B9,2) -> 07 | I9: =MID(B9,2,3) -> 107
B13: Vlookup | C13: Laptop | D13: =VLOOKUP(C13,$A$1:$E$9,3,0) -> Turner LLC
C14: Chair | D14: =VLOOKUP(C14,$A$1:$E$9,3,0) -> Shelton PLC
C15: Desk | D15: =VLOOKUP(C15,$A$1:$E$9,3,0) -> Peters-Bell
C16: Monitor | D16: =VLOOKUP(C16,$A$1:$E$9,3,0) -> Murray, Gray and Mitchell
C17: Printer | D17: =VLOOKUP(C17,$A$1:$E$9,3,0) -> Gutierrez LLC
C18: Pen | D18: =VLOOKUP(C18,$A$1:$E$9,3,0) -> Mcfarland-Jimenez
C19: Notebook | D19: =VLOOKUP(C19,$A$1:$E$9,3,0) -> Weeks and Sons
C20: Table | D20: =VLOOKUP(C20,$A$1:$E$9,3,0) -> Cohen Ltd
B23: Xlookup | C23: Laptop | D23: =_xlfn.XLOOKUP(C23,$A$2:$A$9,$D$2:$D$9,"Not Found",0,1) -> 38
C24: Chair | D24: =_xlfn.XLOOKUP(C24,$A$2:$A$9,$D$2:$D$9,"Not Found",0,1) -> 39
C25: Desk | D25: =_xlfn.XLOOKUP(C25,$A$2:$A$9,$D$2:$D$9,"Not Found",0,1) -> 48
C26: Monitor | D26: =_xlfn.XLOOKUP(C26,$A$2:$A$9,$D$2:$D$9,"Not Found",0,1) -> 34
C27: Printer | D27: =_xlfn.XLOOKUP(C27,$A$2:$A$9,$D$2:$D$9,"Not Found",0,1) -> 17
C28: Pen | D28: =_xlfn.XLOOKUP(C28,$A$2:$A$9,$D$2:$D$9,"Not Found",0,1) -> 67
C29: Notebook | D29: =_xlfn.XLOOKUP(C29,$A$2:$A$9,$D$2:$D$9,"Not Found",0,1) -> 25
C30: Table | D30: =_xlfn.XLOOKUP(C30,$A$2:$A$9,$D$2:$D$9,"Not Found",0,1) -> 81

Sheet  Charts
A3: Row Labels | B3: Sum of Total Sales | K3: Row Labels | L3: Sum of Total Sales
A4: East | B4: 604407.96 | K4: East | L4: 604407.96
A5: North | B5: 637809.11 | K5: Electronics | L5: 211359.11
A6: South | B6: 631117.14 | K6: Furniture | L6: 199728.57
A7: West | B7: 595706.23 | K7: Office Supplies | L7: 193320.28
A8: Grand Total | B8: 2469040.4 | K8: North | L8: 637809.11
K9: Electronics | L9: 202077.75
K10: Furniture | L10: 231904.62
K11: Office Supplies | L11: 203826.74
K12: South | L12: 631117.14
K13: Electronics | L13: 204364.85
K14: Furniture | L14: 223815.13
K15: Office Supplies | L15: 202937.16
K16: West | L16: 595706.23
K17: Electronics | L17: 191713.33
K18: Furniture | L18: 212622.84
K19: Office Supplies | L19: 191370.06
K20: Grand Total | L20: 2469040.4
A22: Row Labels | B22: Sum of Total Sales
A23: 2023 | B23: 939660.22
A24: Qtr2 | B24: 313256.52
A25: Qtr3 | B25: 305355.47
A26: Qtr4 | B26: 321048.23
A27: 2024 | B27: 1188992.9
A28: Qtr1 | B28: 291545.87
A29: Qtr2 | B29: 307393.33
A30: Qtr3 | B30: 316199.21
A31: Qtr4 | B31: 273854.47
A32: 2025 | B32: 340387.34
A33: Qtr1 | B33: 325665.46
A34: Qtr2 | B34: 14721.88
A35: Grand Total | B35: 2469040.4
A61: Years (Order Date) | B61: Months (Order Date) | C61: Order Date | D61: Sum of Total Sales
A62: 2023 | D62: 939660.22
A63: 2024 | D63: 1188992.9
A64: 2025 | D64: 340387.34
A65: Grand Total | D65: 2469040.4
E107: .

Sheet Pivot table
A1: Order Date (Month) | B1: (Multiple Items) | E1: Column Labels
E2: Electronics | F2: Furniture | G2: Office Supplies | H2: Grand Total
A3: Row Labels | B3: Sum of Total Sales | D3: Sum of Unit Price | E3: 166548.08 | F3: 176282.25 | G3: 165595.34 | H3: 508425.67
A4: 2024 | B4: 175862.44
A5: 2025 | B5: 223813.72 | D5: histogram
A6: Grand Total | B6: 399676.16
A15: Order Date (Year) | B15: All
A16: Order Date (Quarter) | B16: All
A18: Count of Product Category | B18: Column Labels
A19: Row Labels | B19: East | C19: North | D19: South | E19: West | F19: Grand Total
A20: Jan | B20: 34 | C20: 22 | D20: 22 | E20: 20 | F20: 98
A21: Feb | B21: 32 | C21: 22 | D21: 19 | E21: 17 | F21: 90
A22: Mar | B22: 20 | C22: 15 | D22: 21 | E22: 24 | F22: 80
A23: Apr | B23: 19 | C23: 20 | D23: 17 | E23: 16 | F23: 72
A24: May | B24: 17 | C24: 14 | D24: 21 | E24: 16 | F24: 68
A25: Jun | B25: 19 | C25: 25 | D25: 28 | E25: 19 | F25: 91
A26: Jul | B26: 27 | C26: 21 | D26: 24 | E26: 27 | F26: 99
A27: Aug | B27: 19 | C27: 16 | D27: 20 | E27: 18 | F27: 73
A28: Sep | B28: 23 | C28: 19 | D28: 22 | E28: 13 | F28: 77
A29: Oct | B29: 5 | C29: 23 | D29: 20 | E29: 27 | F29: 75
A30: Nov | B30: 29 | C30: 26 | D30: 22 | E30: 15 | F30: 92
A31: Dec | B31: 25 | C31: 27 | D31: 18 | E31: 15 | F31: 85
A32: Grand Total | B32: 269 | C32: 250 | D32: 254 | E32: 227 | F32: 1000

Sheet Dashboard
A2: Order Date (Month) | B2: All
A3: Order Date (Quarter) | B3: All
A4: Order Date | B4: All
Q5: East | R5: Sum of Total Revenue | S5: North | T5: Sum of Total Revenue | U5: South | V5: Sum of Total Revenue | W5: West | X5: Sum of Total Revenue
A6: Sum of Total Revenue | B6: Column Labels | Q6: Notebook | R6: 105831.67 | S6: Chair | T6: 102677.66 | U6: Printer | V6: 107095.05 | W6: Laptop | X6: 113976.68
A7: Row Labels | B7: East | C7: North | D7: South | E7: West | F7: Grand Total | Q7: Printer | R7: 92041.69 | S7: Notebook | T7: 98413.72 | U7: Notebook | V7: 97995.28 | W7: Printer | X7: 91491.14
A8: Electronics | Q8: Pen | R8: 84385 | S8: Desk | T8: 91391.74 | U8: Chair | V8: 93346.75 | W8: Chair | X8: 75962.5
A9: Chair | B9: 36334.48 | C9: 22500.87 | D9: 44747.18 | E9: 39661 | F9: 143243.53 | Q9: Chair | R9: 76164.56 | S9: Monitor | T9: 86070.59 | U9: Table | V9: 79899.97 | W9: Pen | X9: 70020.16
A10: Desk | B10: 19929.95 | C10: 20267.84 | D10: 12782.69 | E10: 24923.88 | F10: 77904.36 | Q10: Table | R10: 67121.97 | S10: Printer | T10: 81521.55 | U10: Desk | V10: 65323.75 | W10: Table | X10: 66046.19
A11: Laptop | B11: 12359.64 | C11: 23068.32 | D11: 13022.72 | E11: 17973.55 | F11: 66424.23 | Q11: Desk | R11: 61641.4 | S11: Laptop | T11: 70426.55 | U11: Pen | V11: 65103.78 | W11: Desk | X11: 62315.75
A12: Monitor | B12: 33280.59 | C12: 30478.44 | D12: 16914.41 | E12: 25486.79 | F12: 106160.23 | Q12: Monitor | R12: 59339 | S12: Table | T12: 54189.44 | U12: Monitor | V12: 64362.14 | W12: Notebook | X12: 59387
A13: Notebook | B13: 24906.82 | C13: 31041.52 | D13: 20962.33 | E13: 20923.4 | F13: 97834.07 | Q13: Laptop | R13: 57882.67 | S13: Pen | T13: 53117.86 | U13: Laptop | V13: 57990.42 | W13: Monitor | X13: 56506.81
A14: Pen | B14: 24099.86 | C14: 19224.15 | D14: 15657.99 | E14: 22242.96 | F14: 81224.96
A15: Printer | B15: 21972.38 | C15: 43468.2 | D15: 62693.83 | E15: 29234.5 | F15: 157368.91 | Q15: Total Revenue | R15: Column Labels
A16: Table | B16: 38475.39 | C16: 12028.41 | D16: 17583.7 | E16: 11267.25 | F16: 79354.75 | Q16: Row Labels | R16: East | S16: North | T16: South | U16: West | V16: Grand Total
A17: Furniture | Q17: Chair | R17: 76164.56 | S17: 102677.66 | T17: 93346.75 | U17: 75962.5 | V17: 348151.47
A18: Chair | B18: 27970.09 | C18: 40614.92 | D18: 26805.63 | E18: 8147.87 | F18: 103538.51 | Q18: Desk | R18: 61641.4 | S18: 91391.74 | T18: 65323.75 | U18: 62315.75 | V18: 280672.64
A19: Desk | B19: 7971.73 | C19: 58858.63 | D19: 23431.24 | E19: 4953.45 | F19: 95215.05 | Q19: Laptop | R19: 57882.67 | S19: 70426.55 | T19: 57990.42 | U19: 113976.68 | V19: 300276.32
A20: Laptop | B20: 31330.72 | C20: 33539.3 | D20: 32940.55 | E20: 60442.95 | F20: 158253.52 | Q20: Monitor | R20: 59339 | S20: 86070.59 | T20: 64362.14 | U20: 56506.81 | V20: 266278.54
A21: Monitor | B21: 12544.05 | C21: 22607.04 | D21: 31537.96 | E21: 15727.55 | F21: 82416.6 | Q21: Notebook | R21: 105831.67 | S21: 98413.72 | T21: 97995.28 | U21: 59387 | V21: 361627.67
A22: Notebook | B22: 43378.57 | C22: 23822.15 | D22: 35689.72 | E22: 24499.27 | F22: 127389.71 | Q22: Pen | R22: 84385 | S22: 53117.86 | T22: 65103.78 | U22: 70020.16 | V22: 272626.8
A23: Pen | B23: 16170.22 | C23: 12487.68 | D23: 13774.27 | E23: 38697.02 | F23: 81129.19 | Q23: Printer | R23: 92041.69 | S23: 81521.55 | T23: 107095.05 | U23: 91491.14 | V23: 372149.43
A24: Printer | B24: 50049.05 | C24: 23094.88 | D24: 18032.18 | E24: 16975.83 | F24: 108151.94 | Q24: Table | R24: 67121.97 | S24: 54189.44 | T24: 79899.97 | U24: 66046.19 | V24: 267257.57
A25: Table | B25: 10314.14 | C25: 16880.02 | D25: 41603.58 | E25: 43178.9 | F25: 111976.64 | Q25: Grand Total | R25: 604407.96 | S25: 637809.11 | T25: 631117.14 | U25: 595706.23 | V25: 2469040.4
A26: Office Supplies
A27: Chair | B27: 11859.99 | C27: 39561.87 | D27: 21793.94 | E27: 28153.63 | F27: 101369.43 | S27: Row Labels | T27: Total Revenue
A28: Desk | B28: 33739.72 | C28: 12265.27 | D28: 29109.82 | E28: 32438.42 | F28: 107553.23 | S28: North | T28: 637809.11
A29: Laptop | B29: 14192.31 | C29: 13818.93 | D29: 12027.15 | E29: 35560.18 | F29: 75598.57 | S29: South | T29: 631117.14
A30: Monitor | B30: 13514.36 | C30: 32985.11 | D30: 15909.77 | E30: 15292.47 | F30: 77701.71 | S30: East | T30: 604407.96
A31: Notebook | B31: 37546.28 | C31: 43550.05 | D31: 41343.23 | E31: 13964.33 | F31: 136403.89 | S31: West | T31: 595706.23
A32: Pen | B32: 44114.92 | C32: 21406.03 | D32: 35671.52 | E32: 9080.18 | F32: 110272.65 | S32: Grand Total | T32: 2469040.4
A33: Printer | B33: 20020.26 | C33: 14958.47 | D33: 26369.04 | E33: 45280.81 | F33: 106628.58
A34: Table | B34: 18332.44 | C34: 25281.01 | D34: 20712.69 | E34: 11600.04 | F34: 75926.18
A35: Grand Total | B35: 604407.96 | C35: 637809.11 | D35: 631117.14 | E35: 595706.23 | F35: 2469040.4

Sheet Assignment KC House Data
A1: KC House Data | B1: Data Cleaning & Formulas (Task 1–6)
B2: 1. Convert the "date" column to Date format and extract Year & Month.
B3: (Use YEAR() and TEXT() functions)
B4: 2. Create a new column to calculate Price per Sqft = price / sqft_living.
B5: 3. Classify homes into size categories: "Small", "Medium", "Large" based on sqft_living.
B6: (Hint: Use IF() and thresholds like <1000, 1000–2000, >2000)
B7: 4. Split the latitude and longitude into separate columns for visual mapping (if not already separate).
B8: 5. Create a column to check if a house is newly renovated (use: IF(yr_renovated > 0, "Yes", "No")).
B9: 6. Use Text to Columns to separate zipcode (e.g., prefix first 3 digits vs. last 2 for regional grouping).
B10: Pivot Table Analysis (Task 7–11)
B11: 7. Create a Pivot Table summarizing Average Price by bedrooms.
B12: 8. Build a Pivot Table showing Total Houses and Avg. Price by condition.
B13: 9. Create a Pivot Table to compare Avg. Price and Avg. Sqft Living by grade.
... B24: 18. Highlight rows where condition = 1 or 2 (poor condition).
B25: Dashboard Creation Elements (Task 19–20) | C25: Note: Add all the charts from Chart Creation Questions and If you observe that some more interactive charts can be added please add those as well
B26: 19. Create a mini dashboard showing:
B27: Average Price
B28: Total Number of Houses
B29: Average Sqft Living
B30: (Use AVERAGE(), COUNTA(), SUM())
B31: 20. Build an interactive dashboard with:
B32: Pivot Chart for Price by Grade
B33: Slicers for Bedrooms and Zipcode
B34: KPIs like % of Renovated Houses, Average Price per Zip Code

Sheet Assignment SuperStore Data
A1: SuperStore Data | B1: Data Cleaning & Formulas (Task 1–6)
A2: Data is Attached with the File | B2: 1. Convert "Order Date" and "Ship Date" columns to proper Date format.
B3: 2. Calculate "Shipping Duration" = Ship Date - Order Date.
B4: 3. Extract Year and Month from "Order Date" using YEAR() and TEXT() formulas.
B5: 4. Split "Customer Name" into First Name and Last Name using Text to Columns.
B6: 5. Remove duplicates based on "Order ID".
B7: 6. Create a new column to classify orders as "High", "Medium", or "Low" value based on Sales.
B8: (Tip: Use IF() formula)
B9: Pivot Table Analysis (Task 7–11)
B10: 7. Create a Pivot Table to calculate Total Sales and Profit by Region.
B11: 8. Build a Pivot Table showing Category-wise Sales per State.
B12: 9. Create a Pivot Table to analyze Discount vs. Profit for each Sub-Category.
B13: 10. Add a Slicer for Segment in any Pivot Table.
B14: 11. Summarize Quantity sold by Ship Mode using Pivot Table.
... B23: 18. Highlight rows with more than 20% Discount using a custom rule.
B24: Dashboard Creation Elements (Task 19–20) | C24: Note: Add all the charts from Chart Creation Questions and If you observe that some more interactive charts can be added please add those as well
B25: 19. Create a mini dashboard combining:
B26: Total Sales
B27: Total Profit
B28: Average Discount
B29: (Use SUM(), AVERAGE() and TEXT() formulas with cell formatting)
B30: 20. Create an interactive dashboard using:
B31: Pivot Charts
B32: Slicers for Region and Segment
B33: KPIs like Total Orders and Top Category

Sheet Assignment Employee-Attrition D
B1: Data Cleaning & Formulas (Task 1–6)
B2: 1. Use IF() to create a column labeling employees as “Long Tenure” or “Short Tenure” based on YearsAtCompany > 5.
B3: 2. Convert categorical columns like Attrition, Gender, and OverTime into numerical values using IF() for analysis.
B4: 3. Extract Age Group: “<30”, “30-40”, “>40” using IF() in a new column.
B5: 4. Clean up JobRole column if it has extra spaces or inconsistent case (use TRIM(), PROPER()).
B6: 5. Create a new column AnnualIncome = MonthlyIncome * 12.
B7: 6. Use Text to Columns to split EducationField if it's composite (like “Business – Finance”).
B8: Pivot Table Analysis (Task 7–11)
B9: 7. Create a Pivot Table to count employees by Department.
B10: 8. Show Average Monthly Income by JobRole.
B11: 9. Use a Pivot Table to compare Attrition Rate by EducationField.
B12: 10. Add a Slicer to filter any Pivot Table by Gender.
... B22: 18. Color cells in PerformanceRating below 3 in orange.
B23: Dashboard Creation Elements (Task 19–20) | C23: Note: Add all the charts from Chart Creation Questions and If you observe that some more interactive charts can be added please add those as well
B24: 19. Create a mini KPI Dashboard showing:
B25: Total Employees
B26: Attrition %
B27: Avg Monthly Income
B28: Avg WorkLifeBalance Score
B29: (Use COUNTIF(), AVERAGE(), etc.)
B30: 20. Build an interactive dashboard with:
B31: Pivot Charts (Attrition by JobRole, by Age Group)
B32: Slicers for Department & Gender
B33: KPIs like: Employees with High Performance + Low Satisfaction

Sheet Assignment Bank data
A1: Bank Data | B1: Data Cleaning & Formulas (Task 1–6)
B2: 1. Create an Age Group column:
B3: (Use IF() to group into <30, 30-50, >50)
B4: 2. Use IF() to label customers as "Debtor" or "Non-Debtor" based on the loan and housing columns.
B5: 3. Standardize the job column using PROPER() function.
B6: 4. Convert month to numeric format using CHOOSE() or a helper column.
B7: 5. Use Text to Columns on contact if it includes multiple values (e.g., "cellular-sms").
B8: 6. Create a new column Total Contacts = campaign + previous.
B9: Pivot Table Analysis (Task 7–11)
B10: 7. Create a Pivot Table to count deposits (deposit = yes) by job.
B11: 8. Show average balance by education level.
B12: 9. Use Pivot Table to calculate deposit rate by marital status.
B13: 10. Add a slicer to filter by month or contact type.
... B23: 18. Use color scale on duration to show longer calls in green, shorter in red.
B24: Dashboard Creation Elements (Task 19–20) | C24: Note: Add all the charts from Chart Creation Questions and If you observe that some more interactive charts can be added please add those as well
B25: 19. Build a KPI dashboard showing:
B26: Total Customers
B27: % Deposit Subscribed
B28: Avg Call Duration
B29: Avg Campaign Contacts
B30: 20. Create an interactive dashboard with:
B31: Slicers for job, education, contact
B32: Pivot Charts (Deposits by job, age group, contact)
B33: KPIs like Conversion Rate (deposit = yes / total)

Sheet Assignment Ecommercedata
A1: Ecommercedata | B1: Data Cleaning & Formulas (Task 1–6)
B2: 1. Create a new column for Total Price = Quantity * UnitPrice.
B3: 2. Extract the month from InvoiceDate using TEXT() or MONTH().
B4: 3. Use IF() to tag rows where Quantity < 0 as “Returns”.
B5: 4. Use LEFT() to extract country code if present in StockCode or InvoiceNo.
B6: 5. Clean the Description column using TRIM() and PROPER() functions.
B7: 6. Use Text to Columns to split InvoiceDate into Date and Time (if datetime is included).
B8: Pivot Table Analysis (Task 7–11)
B9: 7. Create a Pivot Table showing total sales by Country.
B10: 8. Analyze average unit price per StockCode using Pivot Table.
B11: 9. Create a Pivot Table showing the number of invoices per month.
B12: 10. Use Pivot Table to summarize total quantity sold by Description.
B13: 11. Add a Slicer to filter any Pivot Table by Country.
... B22: 18. Use Color Scale on UnitPrice to show pricing variation.
B23: _xDCCC_ Dashboard Creation Elements (Task 19–20) | C23: Note: Add all the charts from Chart Creation Questions and If you observe that some more interactive charts can be added please add those as well
B24: 19. Design KPI Cards using formulas to show:
B25: Total Sales
B26: Number of Unique Products
B27: Total Orders
B28: Avg Order Value
B29: 20. Build an interactive dashboard with:
B30: Pivot Charts for monthly sales, top customers
B31: Slicers for Country and Product
B32: Key insights on sales and returns
